Workbook

Sheet Итог
A1: Парк на месте болота, Архангельск — сводка сметы
A2: Синие числа — исходные допущения, их можно менять. Остальное считается формулами.
A4: Допущения
A5: Непредвиденные, % от прямых | B5: 0.12
A6: Проектирование, % от прямых | B6: 0.06
A7: Технадзор, % от прямых | B7: 0.03
A8: Экспертиза, % от прямых | B8: 0.008
A9: Инженерные изыскания, ₽ | B9: 4200000
A10: НДС | B10: 0.22
A11: Включить ресторан «Тоня» в бюджет (1 — да, 0 — нет) | B11: 0
A14: Разделы | B14: Прямые затраты, ₽
A15: 1. Подготовка территории | B15: =Ведомость!F7 -> 8082670.5
A16: 2. Водоём из болота: земляные работы и гидротехника | B16: =Ведомость!F27 -> 58214436
A17: 3. Дороги, площадки, настилы | B17: =Ведомость!F40 -> 64668805
A18: 4. Здания и сооружения | B18: =Ведомость!F51 -> 104872000
A19: 5. Детская, спортивная и собачья зоны | B19: =Ведомость!F65 -> 18555750
A20: 6. Озеленение | B20: =Ведомость!F89 -> 60630636
A21: 7. Ливневая система и биоинженерия | B21: =Ведомость!F96 -> 12242050
A22: 8. Инженерные сети и освещение | B22: =Ведомость!F107 -> 27989035
A23: 9. Малые архитектурные формы и навигация | B23: =Ведомость!F120 -> 13509000
A24: 10. Ресторан «Тоня» (по умолчанию — за счёт инвестора-арендатора) | B24: =Ведомость!F127 -> 127228000
A26: Прямые затраты парка | B26: =SUM(B15:B23)+B24*$B$11 -> 368764383
A27: Непредвиденные | B27: =B26*$B$5 -> 44251726
A28: Проектирование | B28: =B26*$B$6 -> 22125863
A29: Технадзор | B29: =B26*$B$7 -> 11062931
A30: Экспертиза | B30: =B26*$B$8 -> 2950115.1
A31: Изыскания | B31: =$B$9 -> 4200000
A32: Итого без НДС | B32: =SUM(B26:B31) -> 4.5335502e+08
A33: НДС | B33: =B32*$B$10 -> 99738104
A34: ИТОГО С НДС | B34: =B32+B33 -> 5.5309312e+08
A36: Ресторан отдельно, с резервами и НДС | B36: =B24*(1+$B$5+$B$6+$B$7+$B$8)*(1+$B$10) -> 1.8905572e+08
A37: Итог в млн ₽ | B37: =B34/1000000 -> 553.09312

Sheet Ведомость
A1: № | B1: Наименование работ и затрат | C1: Ед. | D1: Количество | E1: Цена за ед., ₽ | F1: Сумма, ₽ | G1: Примечание
A2: 1 | B2: Подготовка территории
A3: 1.1 | B3: Ограждение стройплощадки (профнастил H=2 м) | C3: м | D3: 1306.6 | E3: 1150 | F3: =D3*E3 -> 1502590 | G3: периметр участка
A4: 1.2 | B4: Расчистка: срезка кустарника и мелколесья, вывоз порубочных остатков и мусора | C4: м² | D4: 78194.5 | E4: 38 | F4: =D4*E4 -> 2971391 | G4: вся суша участка
A5: 1.3 | B5: Геодезическая разбивка и вынос осей в натуру | C5: м² | D5: 101965.5 | E5: 9 | F5: =D5*E5 -> 917689.5 | G5: вся площадь участка
A6: 1.4 | B6: Временные технологические проезды из дорожных плит (аренда, укладка, демонтаж) | C6: м² | D6: 2340 | E6: 1150 | F6: =D6*E6 -> 2691000 | G6: 520 м × 4,5 м
B7: Итого по разделу | F7: =SUM(F3:F6) -> 8082670.5
A9: 2 | B9: Водоём из болота: земляные работы и гидротехника
A10: 2.1 | B10: Водопонижение и перемычки: организация сухих карт на акватории | C10: м² | D10: 23771 | E10: 95 | F10: =D10*E10 -> 2258245 | G10: площадь воды по проекту
A11: 2.2 | B11: Разработка торфа и сапропеля в акватории экскаватором с матов (глубина от 0,30 м до проектной) | C11: м³ | D11: 26873.8 | E11: 640 | F11: =D11*E11 -> 17199232 | G11: V = ∫(h проект − 0,30 м) dA
A12: 2.3 | B12: Перемещение торфа на карты подсушки (≤ 250 м), укладка слоями | C12: м³ | D12: 26873.8 | E12: 310 | F12: =D12*E12 -> 8330878
A13: 2.4 | B13: Отсыпка из торфо-грунтовой смеси: берма, холм башни, подъём отметок зон, откосы берегов | C13: м³ | D13: 19184.9 | E13: 540 | F13: =D13*E13 -> 10359846 | G13: берма 4 511 + холм 4 222 + подъём 9 525 + откосы 927
A14: 2.5 | B14: Привозной минеральный грунт (дефицит после усадки торфа) | C14: м³ | D14: 373.2 | E14: 980 | F14: =D14*E14 -> 365736 | G14: усадка торфа при подсушке принята 30 %
A15: 2.6 | B15: Профилирование дна и откосов 1:4, шельф 0,45 м | C15: м² | D15: 23771 | E15: 85 | F15: =D15*E15 -> 2020535 | G15: тонкая планировка под водой
A16: 2.7 | B16: Каскад из 3 ступеней (ЖБ + облицовка природным камнем), перепад 0,9 м | C16: ст. | D16: 3 | E16: 1150000 | F16: =D16*E16 -> 3450000 | G16: канал 8 м шириной
A17: 2.8 | B17: Укрепление уреза кокосовыми биоваликами Ø30 см | C17: м | D17: 1287 | E17: 1250 | F17: =D17*E17 -> 1608750 | G17: береговая линия, включая полуостров
A18: 2.9 | B18: Кокосовый биомат на откосах (ширина 2,2 м) | C18: м² | D18: 2831.5 | E18: 410 | F18: =D18*E18 -> 1160915
A19: 2.10 | B19: Каменная наброска у пирсов и каскада | C19: м³ | D19: 150 | E19: 6800 | F19: =D19*E19 -> 1020000
A20: 2.11 | B20: Водовыпуск и регулятор уровня (переливной колодец, труба Ø600 в существующий водоотвод) | C20: компл. | D20: 1 | E20: 1850000 | F20: =D20*E20 -> 1850000
A21: 2.12 | B21: Рециркуляционная насосная станция 30 л/с | C21: компл. | D21: 1 | E21: 2350000 | F21: =D21*E21 -> 2350000 | G21: полный оборот воды ≈ 13 сут
A22: 2.13 | B22: Напорный трубопровод ПНД Ø250 | C22: м | D22: 176.2 | E22: 4600 | F22: =D22*E22 -> 810520 | G22: пруд 2 → верховье пруда 1
A23: 2.14 | B23: Донная аэрация (компрессор + диффузоры), пруды 1 и 2 | C23: компл. | D23: 2 | E23: 1550000 | F23: =D23*E23 -> 3100000
A24: 2.15 | B24: Литораль: водные и прибрежные растения (60 % шельфа, 7 шт/м²) | C24: шт. | D24: 14759.8 | E24: 105 | F24: =D24*E24 -> 1549779 | G24: тростник, рогоз, аир, ирис болотный, сабельник, калужница
A25: 2.16 | B25: Растения глубокой воды: кувшинка белая, кубышка | C25: шт. | D25: 400 | E25: 650 | F25: =D25*E25 -> 260000
A26: 2.17 | B26: Биологическая подготовка водоёма: зоопланктон, моллюски-фильтраторы, фитофаги | C26: компл. | D26: 1 | E26: 520000 | F26: =D26*E26 -> 520000
B27: Итого по разделу | F27: =SUM(F10:F26) -> 58214436
A29: 3 | B29: Дороги, площадки, настилы
A30: 3.1 | B30: Главные аллеи 3,0 м: цветной асфальтобетон на основании (геосетка, щебень 25 см, ПГС) | C30: м² | D30: 3442.8 | E30: 5200 | F30: =D30*E30 -> 17902560 | G30: длина 1 107 м
A31: 3.2 | B31: Второстепенные дорожки 2,0–2,5 м: каменная мелочь с вяжущим на геотекстиле | C31: м² | D31: 2113 | E31: 3100 | F31: =D31*E31 -> 6550300 | G31: длина 923 м
A32: 3.3 | B32: Беговая дорожка 3,0 м: EPDM-покрытие по асфальту | C32: м² | D32: 903.5 | E32: 6200 | F32: =D32*E32 -> 5601700 | G32: длина 264 м
A33: 3.4 | B33: Входная площадь: гранитная плитка | C33: м² | D33: 709.5 | E33: 11200 | F33: =D33*E33 -> 7946400
A34: 3.5 | B34: Деревянные настилы на винтовых сваях (лиственница): мостки, пирсы, мостик каскада, йога-настил | C34: м² | D34: 598 | E34: 26000 | F34: =D34*E34 -> 15548000
A35: 3.6 | B35: Перила настилов (лиственница) | C35: м | D35: 237.6 | E35: 8200 | F35: =D35*E35 -> 1948320 | G35: с двух сторон
A36: 3.7 | B36: Бортовой камень вдоль главных аллей и площади | C36: м | D36: 2418.5 | E36: 1450 | F36: =D36*E36 -> 3506825
A37: 3.8 | B37: Покрытие служебного двора: щебень по геотекстилю | C37: м² | D37: 1298 | E37: 1850 | F37: =D37*E37 -> 2401300
A38: 3.9 | B38: Хозяйственный проезд к ресторану (асфальтобетон по щебню, совмещён с пожарным) | C38: м² | D38: 530 | E38: 5200 | F38: =D38*E38 -> 2756000 | G38: 66 м от проспекта + двор
A39: 3.10 | B39: Подходы к павильонам и ресторану (плитка) | C39: м² | D39: 118 | E39: 4300 | F39: =D39*E39 -> 507400
B40: Итого по разделу | F40: =SUM(F30:F39) -> 64668805
A42: 4 | B42: Здания и сооружения
A43: 4.1 | B43: Смотровая башня H = 18 м (дерево/сталь, 2 площадки), на холме 7 м | C43: шт. | D43: 1 | E43: 15800000 | F43: =D43*E43 -> 15800000 | G43: фундамент — винтовые сваи через насыпь
...
